Workbook

Sheet 1. Accueil
B2: OUTIL DE PILOTAGE — SUIVI-ÉVALUATION DES PERFORMANCES
B3: ONG Equi-Filles | Projets EQUIFILLES (FoSIR) & SPACE TO LEAD (Plan International Bénin)
B5: ◆ IDENTIFICATION DU SYSTÈME | H5: ◆ SÉLECTEUR DE PROJET
B6: Version | D6: 1.0 | H6: Choisir un projet : | J6: Tous les projets
B7: Date de mise en service | D7: 01/03/2026 | H7: ↑ Cliquez sur la cellule ci-dessus pour choisir un projet — les chiffres et le graphique s'adaptent
B8: Référence S2L | D8: Activité An1 — 435 000 FCFA
B9: Préparé par | D9: Ibrahima KOTO | H9: ◆ CHIFFRES CLÉS DU PROJET SÉLECTIONNÉ
B10: Assisté de | D10: Pierre FABOUL | H10: Indicateur | L10: Valeur
B11: Validé par | D11: KASSIMOU Mountarou (DE) | H11: Activités planifiées | L11: =IF($J$6="EQUIFILLES",COUNTA('5. Gantt EQUIFILLES'!B6:B205)-COUNTBLANK('5. Gantt EQUIFILLES'!B6:B205),IF($J$6="SPACE TO LEAD",COUNTA('10. Gantt S2L'!B6:B205)-COUNTBLANK('10. Gantt S2L'!B6:B205),COUNTA('5. Gantt EQUIFILLES'!B6:B205)+COUNTA('10. Gantt S2L'!B6:B205)-COUNTBLANK('5. Gantt EQUIFILLES'!B6:B205)-COUNTBLANK('10. Gantt S2L'!B6:B205))) -> -300
H12: Activités terminées | L12: =IF($J$6="EQUIFILLES",COUNTIF('5. Gantt EQUIFILLES'!Q6:Q205,"Terminé à temps")+COUNTIF('5. Gantt EQUIFILLES'!Q6:Q205,"Terminé hors délai"),IF($J$6="SPACE TO LEAD",COUNTIF('10. Gantt S2L'!Q6:Q205,"Terminé à temps")+COUNTIF('10. Gantt S2L'!Q6:Q205,"Terminé hors délai"),COUNTIF('5. Gantt EQUIFILLES'!Q6:Q205,"Terminé à temps")+COUNTIF('5. Gantt EQUIFILLES'!Q6:Q205,"Terminé hors délai")+COUNTIF('10. Gantt S2L'!Q6:Q205,"Terminé à temps")+COUNTIF('10. Gantt S2L'!Q6:Q205,"Terminé hors délai"))) -> 0
H13: Activités en retard | L13: =IF($J$6="EQUIFILLES",COUNTIF('5. Gantt EQUIFILLES'!Q6:Q205,"En retard"),IF($J$6="SPACE TO LEAD",COUNTIF('10. Gantt S2L'!Q6:Q205,"En retard"),COUNTIF('5. Gantt EQUIFILLES'!Q6:Q205,"En retard")+COUNTIF('10. Gantt S2L'!Q6:Q205,"En retard"))) -> 21
H14: Activités critiques | L14: =IF($J$6="EQUIFILLES",COUNTIF('5. Gantt EQUIFILLES'!Q6:Q205,"Critique"),IF($J$6="SPACE TO LEAD",COUNTIF('10. Gantt S2L'!Q6:Q205,"Critique"),COUNTIF('5. Gantt EQUIFILLES'!Q6:Q205,"Critique")+COUNTIF('10. Gantt S2L'!Q6:Q205,"Critique"))) -> 7
H15: Taux d'avancement moyen | L15: =IFERROR(IF($J$6="EQUIFILLES",AVERAGEIF('5. Gantt EQUIFILLES'!B6:B205,"<>",'5. Gantt EQUIFILLES'!N6:N205),IF($J$6="SPACE TO LEAD",AVERAGEIF('10. Gantt S2L'!B6:B205,"<>",'10. Gantt S2L'!N6:N205),(SUMIF('5. Gantt EQUIFILLES'!B6:B205,"<>",'5. Gantt EQUIFILLES'!N6:N205)+SUMIF('10. Gantt S2L'!B6:B205,"<>",'10. Gantt S2L'!N6:N205))/(COUNTIF('5. Gantt EQUIFILLES'!B6:B205,"<>")+COUNTIF('10. Gantt S2L'!B6:B205,"<>"))))/100,0) -> 0
H16: Budget total prévu (FCFA) | L16: =IF($J$6="EQUIFILLES",SUM('5. Gantt EQUIFILLES'!O6:O205),IF($J$6="SPACE TO LEAD",SUM('10. Gantt S2L'!O6:O205),SUM('5. Gantt EQUIFILLES'!O6:O205)+SUM('10. Gantt S2L'!O6:O205))) -> 152708466
H17: Budget consommé (FCFA) | L17: =IF($J$6="EQUIFILLES",SUM('5. Gantt EQUIFILLES'!P6:P205),IF($J$6="SPACE TO LEAD",SUM('10. Gantt S2L'!P6:P205),SUM('5. Gantt EQUIFILLES'!P6:P205)+SUM('10. Gantt S2L'!P6:P205))) -> 0
H18: Taux de consommation budgétaire | L18: =IFERROR(IF($J$6="EQUIFILLES",SUM('5. Gantt EQUIFILLES'!P6:P205)/SUM('5. Gantt EQUIFILLES'!O6:O205),IF($J$6="SPACE TO LEAD",SUM('10. Gantt S2L'!P6:P205)/SUM('10. Gantt S2L'!O6:O205),(SUM('5. Gantt EQUIFILLES'!P6:P205)+SUM('10. Gantt S2L'!P6:P205))/(SUM('5. Gantt EQUIFILLES'!O6:O205)+SUM('10. Gantt S2L'!O6:O205)))),0) -> 0
B30: Statut | C30: Nombre
B31: Terminé à temps | C31: =IF($J$6="EQUIFILLES",COUNTIF('5. Gantt EQUIFILLES'!Q6:Q205,"Terminé à temps"),IF($J$6="SPACE TO LEAD",COUNTIF('10. Gantt S2L'!Q6:Q205,"Terminé à temps"),COUNTIF('5. Gantt EQUIFILLES'!Q6:Q205,"Terminé à temps")+COUNTIF('10. Gantt S2L'!Q6:Q205,"Terminé à temps"))) -> 0
B32: Terminé hors délai | C32: =IF($J$6="EQUIFILLES",COUNTIF('5. Gantt EQUIFILLES'!Q6:Q205,"Terminé hors délai"),IF($J$6="SPACE TO LEAD",COUNTIF('10. Gantt S2L'!Q6:Q205,"Terminé hors délai"),COUNTIF('5. Gantt EQUIFILLES'!Q6:Q205,"Terminé hors délai")+COUNTIF('10. Gantt S2L'!Q6:Q205,"Terminé hors délai"))) -> 0
B33: À temps | C33: =IF($J$6="EQUIFILLES",COUNTIF('5. Gantt EQUIFILLES'!Q6:Q205,"À temps"),IF($J$6="SPACE TO LEAD",COUNTIF('10. Gantt S2L'!Q6:Q205,"À temps"),COUNTIF('5. Gantt EQUIFILLES'!Q6:Q205,"À temps")+COUNTIF('10. Gantt S2L'!Q6:Q205,"À temps"))) -> 0
B34: À surveiller | C34: =IF($J$6="EQUIFILLES",COUNTIF('5. Gantt EQUIFILLES'!Q6:Q205,"À surveiller"),IF($J$6="SPACE TO LEAD",COUNTIF('10. Gantt S2L'!Q6:Q205,"À surveiller"),COUNTIF('5. Gantt EQUIFILLES'!Q6:Q205,"À surveiller")+COUNTIF('10. Gantt S2L'!Q6:Q205,"À surveiller"))) -> 0
B35: En retard | C35: =IF($J$6="EQUIFILLES",COUNTIF('5. Gantt EQUIFILLES'!Q6:Q205,"En retard"),IF($J$6="SPACE TO LEAD",COUNTIF('10. Gantt S2L'!Q6:Q205,"En retard"),COUNTIF('5. Gantt EQUIFILLES'!Q6:Q205,"En retard")+COUNTIF('10. Gantt S2L'!Q6:Q205,"En retard"))) -> 21
B36: Critique | C36: =IF($J$6="EQUIFILLES",COUNTIF('5. Gantt EQUIFILLES'!Q6:Q205,"Critique"),IF($J$6="SPACE TO LEAD",COUNTIF('10. Gantt S2L'!Q6:Q205,"Critique"),COUNTIF('5. Gantt EQUIFILLES'!Q6:Q205,"Critique")+COUNTIF('10. Gantt S2L'!Q6:Q205,"Critique"))) -> 7
B40: ◆ INSTRUCTIONS D'UTILISATION
B41: 1. Choisissez un projet en haut à droite (cellule J6) pour adapter les chiffres et le graphique.
B42: 2. Avant la première utilisation, complétez l'onglet 2 (Paramètres) puis l'onglet 3 (Équipe).
B43: 3. Pour chaque projet, vérifiez le cadre logique (onglets 4 et 9), puis renseignez les Gantt (onglets 5 et 10).
B44: 4. Les indicateurs (onglets 6 et 11) sont alimentés AUTOMATIQUEMENT à partir des Gantt — ne pas modifier ces onglets.
B45: 5. L'onglet de collecte (7 et 12) est alimenté automatiquement par les onglets "Données Kobo" (K1, K2) — voir onglet K3 pour la maquette des formulaires.
B46: 6. Le suivi financier (onglets 14b et 14c) permet le pilotage budget vs avancement physique.
B47: 7. Consultez régulièrement l'onglet 15 (Alertes) pour identifier les activités à risque et les échéances proches.

Sheet 2. Paramètres
B2: PARAMÈTRES DU SYSTÈME
B4: 1. ÉCHELLE DE NOTATION DES STATUTS
B5: Code | C5: Statut | D5: Description | E5: Note (/100) | F5: Couleur
B6: AT | C6: À temps | D6: Avancement réel ≥ avancement prévu | E6: 50
B7: AS | C7: À surveiller | D7: Retard < 7 jours OU 80-99% du prévu | E7: 40
B8: ER | C8: En retard | D8: Retard 7-30 jours OU 50-79% du prévu | E8: 25
B9: CR | C9: Critique | D9: Retard > 30 jours OU < 50% du prévu | E9: 10
B10: TT | C10: Terminé à temps | D10: Activité achevée dans les délais | E10: 100
B11: TH | C11: Terminé hors délai | D11: Objectif atteint mais avec retard | E11: 75
B12: NR | C12: Non réalisé | D12: Activité abandonnée ou annulée | E12: 0
B13: EA | C13: En attente | D13: Date début prévue non encore atteinte | E13: 50
B15: 2. NIVEAUX DE CRITICITÉ DES ACTIVITÉS
B16: Niveau | C16: Libellé | D16: Description | E16: Coefficient
B17: 1 | C17: Courante | D17: Activité d'appui ou de routine | E17: 1
B18: 2 | C18: Importante | D18: Activité contribuant directement à un résultat clé | E18: 2
B19: 3 | C19: Critique | D19: Activité stratégique / livrable majeur | E19: 3
B21: 3. SEUILS DE PERFORMANCE ET D'ALERTE
B22: Paramètre | C22: Valeur | D22: Unité | E22: Description
B23: Seuil retard "À surveiller" | C23: 7 | D23: jours | E23: Au-delà : passe en "En retard"
B24: Seuil retard "En retard" | C24: 30 | D24: jours | E24: Au-delà : passe en "Critique"
B25: Score Excellent | C25: 85 | D25: % | E25: Performance agent ≥ ce seuil = Excellent
B26: Score Satisfaisant | C26: 65 | D26: % | E26: Performance agent ≥ ce seuil = Satisfaisant
B27: Échéances proches (alertes) | C27: 30 | D27: jours | E27: Activités dont échéance < ce nombre de jours
B28: Seuil dépassement budgétaire | C28: 100 | D28: % | E28: Budget consommé > ce % du prévu = alerte
B31: 4. LISTES DE RÉFÉRENCE
B32: Projets | C32: Statuts | D32: Criticité | E32: Périodes | F32: Type collecte | G32: Périodicité
B33: EQUIFILLES | C33: À temps | D33: 1 | E33: T1 2026 | F33: Enquête | G33: Hebdomadaire
B34: SPACE TO LEAD | C34: À surveiller | D34: 2 | E34: T2 2026 | F34: Liste de présence | G34: Bimensuelle
B35: Autre | C35: En retard | D35: 3 | E35: T3 2026 | F35: Données admin | G35: Mensuelle
C36: Critique | E36: T4 2026 | F36: Observation | G36: Trimestrielle
C37: Terminé à temps | E37: T1 2027 | F37: Entretien | G37: Semestrielle
C38: Terminé hors délai | E38: T2 2027 | F38: Documentation | G38: Annuelle
C39: Non réalisé | G39: Ponctuelle
C40: En attente

Sheet 3. Équipe
B2: REGISTRE DE L'ÉQUIPE EQUI-FILLES
B3: Liste extensible — vous pouvez ajouter des agents jusqu'à la ligne 55. Les modifications sont prises en compte automatiquement dans tous les onglets.
B5: Matricule | C5: Nom et Prénom | D5: Fonction | E5: Type contrat | F5: Email | G5: Téléphone | H5: Projet principal | I5: Quotité EQUIFILLES (%) | J5: Quotité S2L (%) | K5: Supérieur hiérarchique
B6: EF001 | C6: KASSIMOU Mountarou | D6: Directeur Exécutif / Management | E6: Permanent | F6: mountarou@gmail.com | G6: 0196073187 | H6: Transverse | I6: 30 | J6: 30 | K6: Conseil d'Administration
B7: EF002 | C7: OLOMONCHIN Francis | D7: Chargé de Programmes (S2L) | E7: Permanent | F7: francislejoyeux@gmail.com | G7: 0195394550 / 0197462333 | H7: SPACE TO LEAD | I7: 0 | J7: 100 | K7: KASSIMOU Mountarou
B8: EF003 | C8: INOUSSA Ousmanou | D8: Responsable Administratif et Financier | E8: Permanent | F8: ousmanouinoussa13@gmail.com | G8: 0166445558 / 0144877819 | H8: SPACE TO LEAD | I8: 30 | J8: 70 | K8: KASSIMOU Mountarou
B9: EF004 | C9: BOUKARI AROUNA Rafiou | D9: Chef Projet (EQUIFILLES) | E9: Permanent | F9: elrafiou2@gmail.com | G9: 0161920442 / 0194616087 | H9: EQUIFILLES | I9: 100 | J9: 0 | K9: KASSIMOU Mountarou
B10: EF005 | C10: BA KOTO Bona Sinani Rebecca | D10: Animatrice (EQUIFILLES) | E10: Permanent | F10: rebeccabonakoto@gmail.com | G10: 0140465291 / 0166096205 | H10: EQUIFILLES | I10: 100 | J10: 0 | K10: BOUKARI AROUNA Rafiou
B11: EF006 | C11: ASSOUMA Nadjibatou | D11: Comptable (EQUIFILLES) | E11: Permanent | F11: nadjibatouassouma138@gmail.com | G11: 0196793183 / 0195052934 | H11: EQUIFILLES | I11: 100 | J11: 0 | K11: BOUKARI AROUNA Rafiou
B12: EF007 | C12: BOUANDI Pierre | D12: Superviseur (Bénévole) | E12: Bénévole | F12: bourandipierre699@gmail.com | G12: 0196706247 / 0195875355 | H12: Transverse | I12: 50 | J12: 50 | K12: KASSIMOU Mountarou
B13: EF008 | C13: MAMA Adou Razak | D13: Facilitateur (Bénévole) | E13: Bénévole | F13: razmamaaboudou@gmail.com | G13: 0161592427 | H13: Transverse | I13: 50 | J13: 50 | K13: BOUANDI Pierre
B14: EF009 | C14: ASSOUMA Amida | D14: Secrétaire Caissière (Bénévole) | E14: Bénévole | F14: amidathassouma@gmail.com | G14: 0195323279 / 0194266607 | H14: Transverse | I14: 50 | J14: 50 | K14: KASSIMOU Mountarou
B15: EF010 | C15: AGONNOUDE Murielle | D15: Facilitatrice (Bénévole) | E15: Bénévole | F15: agonnoudemariquess@gmail.com | G15: 0153051920 | H15: Transverse | I15: 50 | J15: 50 | K15: BOUANDI Pierre
B16: EF011 | C16: AMADOU Nafissatou | D16: Stagiaire | E16: Stagiaire | F16: nafissathdiallo8@gmail.com | G16: 0253481086 | H16: EQUIFILLES | I16: 100 | J16: 0 | K16: BOUKARI AROUNA Rafiou
B17: EF012 | C17: SARE KOMME Joséphine | D17: Stagiaire | E17: Stagiaire | F17: sarekommejosephine@gmail.com | G17: 0158773052 | H17: SPACE TO LEAD | I17: 0 | J17: 100 | K17: OLOMONCHIN Francis
B18: EF013 | C18: GOUDI Simoni | D18: Stagiaire | E18: Stagiaire | F18: goudisimon@gmail.com | G18: 66653479 | H18: Transverse | I18: 50 | J18: 50 | K18: BOUANDI Pierre

Sheet 4. Cadre Logique EQUIFILLES
B2: CADRE LOGIQUE — EQUIFILLES « Classes sûres, filles épanouies »
B3: Projet financé par le FoSIR — Durée : 15 mois (mars 2026 – mai 2027) — Budget : 18 711 453 FCFA (FoSIR 80% + Equi-Filles 20%)
B5: IMPACT
B6: Contribuer à l'amélioration durable de l'accès à une éducation de qualité, équitable et protectrice pour les filles et garçons de Gogounou.
B7: Code | C7: Indicateur | D7: Cible | E7: Source de vérification | F7: Hypothèses | G7: Période | H7: Responsable
B8: Ind 0.1 | C8: Taux d'abandon scolaire des filles réduit | D8: -30% | E8: Enquête + DDEMP | F8: Conditions stables | G8: Final | H8: Chef projet
B9: Ind 0.2 | C9: Niveau de satisfaction parents/élèves | D9: ≥ 75% | E9: Enquête de satisfaction | F9: Participation effective | G9: Annuel | H9: Chef projet
B11: OUTCOME 1
B12: Les communautés éducatives (APE/AME et CGS) exercent un rôle renforcé dans le suivi citoyen des écoles.
B14: OUTPUT 1.1 — Acteurs de l'offre prennent des mesures pour améliorer la qualité
B15: Code | C15: Indicateur | D15: Cible | E15: Source de vérification | F15: Hypothèses | G15: Période | H15: Responsable
B16: Ind 1.1.1 | C16: 30 APE/AME/CAPE et CGS formés | D16: 30 | E16: Attestations formation | F16: Disponibilité acteurs | G16: T1-T2 | H16: Chef projet
B17: Ind 1.1.2 | C17: ≥ 80% APE/AME participent aux cycles | D17: 80% | E17: Listes présence | F17: Mobilisation | G17: T2-T4 | H17: Chef projet
B18: Ind 1.1.3 | C18: 01 rapport d'évaluation citoyenne | D18: 1 | E18: Rapport validé | F18: Implication parties prenantes | G18: T3 | H18: Chef projet
B19: Ind 1.1.4 | C19: Acteurs offre formés aux outils | D19: 15 | E19: Liste présence | F19: Disponibilité prestataires | G19: T2 | H19: Animateur
B20: Ind 1.1.5 | C20: Proportion femmes formées | D20: ≥ 50% | E20: Liste présence ventilée | F20: Engagement femmes | G20: T2 | H20: Animateur
B21: Ind 1.1.6 | C21: Acteurs offre renforcés outils | D21: 15 | E21: Liste présence | F21: Adhésion prestataires | G21: T2-T3 | H21: Animateur
B23: OUTPUT 1.2 — Les élèves, notamment les filles, développent des comportements citoyens
B24: Code | C24: Indicateur | D24: Cible | E24: Source de vérification | F24: Hypothèses | G24: Période | H24: Responsable
B25: Ind 1.2.1 | C25: 75 élèves formés (60% F) | D25: 75 | E25: Liste nominative | F25: Engagement écoles | G25: T1-T2 | H25: Animateur
B26: Ind 1.2.2 | C26: ≥ 70% actions plans clubs réalisées | D26: 70% | E26: Rapports animation | F26: Suivi directions | G26: T3-T5 | H26: Animateur
B28: OUTPUT 1.3 — Les acteurs locaux intègrent les résultats de l'évaluation citoyenne
B29: Code | C29: Indicateur | D29: Cible | E29: Source de vérification | F29: Hypothèses | G29: Période | H29: Responsable
B30: Ind 1.3.1 | C30: ≥ 75% participation parents forums | D30: 75% | E30: Listes présence | F30: Mobilisation | G30: T3-T4 | H30: Chef projet
B31: Ind 1.3.2 | C31: 06 séances concertation | D31: 6 | E31: PV séances | F31: Disponibilité acteurs | G31: T2-T5 | H31: Chef projet
B32: Ind 1.3.3 | C32: ≥ 3 recommandations intégrées plans | D32: 3 | E32: Plans communaux | F32: Engagement autorités | G32: T4-T5 | H32: DE

Sheet 5. Gantt EQUIFILLES
B2: GANTT — SUIVI TEMPOREL DES ACTIVITÉS — EQUIFILLES
B3: Activités et sous-activités liées à un indicateur. Le statut, le score et l'alimentation des indicateurs se calculent automatiquement à partir des dates et du % réel saisi.
B5: Code | C5: Activité / Sous-activité | D5: Output | E5: Responsable principal | F5: Co-responsables | G5: Criticité (1-3) | H5: Date début prévue | I5: Date fin prévue | J5: Date début réelle | K5: Date fin réelle | L5: Jalons / Étapes | M5: % prévu (auto) | N5: % réel (saisir) | O5: Budget prévu (FCFA) | P5: Budget consommé (FCFA) | Q5: Statut (auto) | R5: Note (/100) | S5: Indicateur alimenté | T5: Qté cible | U5: Qté réalisée (auto) | V5: Observations
B6: A0.1 | C6: Lancement officiel du projet | D6: Transverse | E6: KASSIMOU Mountarou | F6: Équipe projet | G6: 2 | H6: 46096 | I6: 46111 | L6: Invitations / Atelier / Communiqué | M6: =IF(OR(H6="",I6=""),0,IF(TODAY()<H6,0,IF(TODAY()>=I6,100,(TODAY()-H6)/(I6-H6)*100))) -> 100 | N6: 0 | O6: 277500 | Q6: =IF(B6="","",IF(K6<>"",IF(K6<=I6,"Terminé à temps","Terminé hors délai"),IF(N6=0,IF(TODAY()<H6,"En attente",IF(TODAY()>I6+30,"Critique","En retard")),IF(N6>=M6,"À temps",IF(N6>=M6*0.8,"À surveiller",IF(N6>=M6*0.5,"En retard","Critique")))))) -> Critique | R6: =IFERROR(IF(Q6="Terminé à temps",100,IF(Q6="Terminé hors délai",75,IF(Q6="À temps",50,IF(Q6="À surveiller",40,IF(Q6="En retard",25,IF(Q6="Critique",10,IF(Q6="En attente",50,0))))))),0) -> 10 | U6: =IFERROR(IF(T6="",0,T6*N6/100),0) -> 0
B7: A1.1.1 | C7: Identification et cartographie des 5 écoles cibles avec CS/DDEMP | D7: Output 1.1 | E7: BOUKARI AROUNA Rafiou | F7: BA KOTO Bona Sinani Rebecca | G7: 2 | H7: 46113 | I7: 46127 | L7: TDR / Mission / Rapport | M7: =IF(OR(H7="",I7=""),0,IF(TODAY()<H7,0,IF(TODAY()>=I7,100,(TODAY()-H7)/(I7-H7)*100))) -> 100 | N7: 0 | O7: 191000 | Q7: =IF(B7="","",IF(K7<>"",IF(K7<=I7,"Terminé à temps","Terminé hors délai"),IF(N7=0,IF(TODAY()<H7,"En attente",IF(TODAY()>I7+30,"Critique","En retard")),IF(N7>=M7,"À temps",IF(N7>=M7*0.8,"À surveiller",IF(N7>=M7*0.5,"En retard","Critique")))))) -> Critique | R7: =IFERROR(IF(Q7="Terminé à temps",100,IF(Q7="Terminé hors délai",75,IF(Q7="À temps",50,IF(Q7="À surveiller",40,IF(Q7="En retard",25,IF(Q7="Critique",10,IF(Q7="En attente",50,0))))))),0) -> 10 | S7: Ind 1.1.3 | T7: 1 | U7: =IFERROR(IF(T7="",0,T7*N7/100),0) -> 0
B8: A1.1.2.1 | C8: Formation acteurs demande - Volet APE/AME formés (15 personnes × 2 ateliers) | D8: Output 1.1 | E8: BOUKARI AROUNA Rafiou | F8: BA KOTO Bona Sinani Rebecca | G8: 3 | H8: 46132 | I8: 46157 | L8: TDR / Module / Atelier / Rapport | M8: =IF(OR(H8="",I8=""),0,IF(TODAY()<H8,0,IF(TODAY()>=I8,100,(TODAY()-H8)/(I8-H8)*100))) -> 100 | N8: 0 | O8: 600000 | Q8: =IF(B8="","",IF(K8<>"",IF(K8<=I8,"Terminé à temps","Terminé hors délai"),IF(N8=0,IF(TODAY()<H8,"En attente",IF(TODAY()>I8+30,"Critique","En retard")),IF(N8>=M8,"À temps",IF(N8>=M8*0.8,"À surveiller",IF(N8>=M8*0.5,"En retard","Critique")))))) -> En retard | R8: =IFERROR(IF(Q8="Terminé à temps",100,IF(Q8="Terminé hors délai",75,IF(Q8="À temps",50,IF(Q8="À surveiller",40,IF(Q8="En retard",25,IF(Q8="Critique",10,IF(Q8="En attente",50,0))))))),0) -> 25 | S8: Ind 1.1.1 | T8: 30 | U8: =IFERROR(IF(T8="",0,T8*N8/100),0) -> 0
B9: A1.1.2.2 | C9: Formation acteurs demande - Volet équilibre H/F (60% femmes) | D9: Output 1.1 | E9: BOUKARI AROUNA Rafiou | F9: BA KOTO Bona Sinani Rebecca | G9: 2 | H9: 46132 | I9: 46157 | L9: Listes ventilées H/F | M9: =IF(OR(H9="",I9=""),0,IF(TODAY()<H9,0,IF(TODAY()>=I9,100,(TODAY()-H9)/(I9-H9)*100))) -> 100 | N9: 0 | O9: 0 | Q9: =IF(B9="","",IF(K9<>"",IF(K9<=I9,"Terminé à temps","Terminé hors délai"),IF(N9=0,IF(TODAY()<H9,"En attente",IF(TODAY()>I9+30,"Critique","En retard")),IF(N9>=M9,"À temps",IF(N9>=M9*0.8,"À surveiller",IF(N9>=M9*0.5,"En retard","Critique")))))) -> En retard | R9: =IFERROR(IF(Q9="Terminé à temps",100,IF(Q9="Terminé hors délai",75,IF(Q9="À temps",50,IF(Q9="À surveiller",40,IF(Q9="En retard",25,IF(Q9="Critique",10,IF(Q9="En attente",50,0))))))),0) -> 25 | S9: Ind 1.1.5 | T9: 18 | U9: =IFERROR(IF(T9="",0,T9*N9/100),0) -> 0
B10: A1.1.2.3 | C10: Formation acteurs demande - Suivi participation aux cycles | D10: Output 1.1 | E10: BOUKARI AROUNA Rafiou | F10: BA KOTO Bona Sinani Rebecca | G10: 2 | H10: 46143 | I10: 46477 | L10: Listes présence cumulées | M10: =IF(OR(H10="",I10=""),0,IF(TODAY()<H10,0,IF(TODAY()>=I10,100,(TODAY()-H10)/(I10-H10)*100))) -> 7.1856287 | N10: 0 | O10: 307000 | Q10: =IF(B10="","",IF(K10<>"",IF(K10<=I10,"Terminé à temps","Terminé hors délai"),IF(N10=0,IF(TODAY()<H10,"En attente",IF(TODAY()>I10+30,"Critique","En retard")),IF(N10>=M10,"À temps",IF(N10>=M10*0.8,"À surveiller",IF(N10>=M10*0.5,"En retard","Critique")))))) -> En retard | R10: =IFERROR(IF(Q10="Terminé à temps",100,IF(Q10="Terminé hors délai",75,IF(Q10="À temps",50,IF(Q10="À surveiller",40,IF(Q10="En retard",25,IF(Q10="Critique",10,IF(Q10="En attente",50,0))))))),0) -> 25 | S10: Ind 1.1.2 | T10: 24 | U10: =IFERROR(IF(T10="",0,T10*N10/100),0) -> 0
B11: A1.1.3.1 | C11: Séance échange acteurs offre - Volet acteurs formés outils redevabilité | D11: Output 1.1 | E11: BOUKARI AROUNA Rafiou | F11: BA KOTO Bona Sinani Rebecca | G11: 2 | H11: 46162 | I11: 46188 | L11: TDR / Atelier / Rapport | M11: =IF(OR(H11="",I11=""),0,IF(TODAY()<H11,0,IF(TODAY()>=I11,100,(TODAY()-H11)/(I11-H11)*100))) -> 19.230769 | N11: 0 | O11: 400000 | Q11: =IF(B11="","",IF(K11<>"",IF(K11<=I11,"Terminé à temps","Terminé hors délai"),IF(N11=0,IF(TODAY()<H11,"En attente",IF(TODAY()>I11+30,"Critique","En retard")),IF(N11>=M11,"À temps",IF(N11>=M11*0.8,"À surveiller",IF(N11>=M11*0.5,"En retard","Critique")))))) -> En retard | R11: =IFERROR(IF(Q11="Terminé à temps",100,IF(Q11="Terminé hors délai",75,IF(Q11="À temps",50,IF(Q11="À surveiller",40,IF(Q11="En retard",25,IF(Q11="Critique",10,IF(Q11="En attente",50,0))))))),0) -> 25 | S11: Ind 1.1.4 | T11: 15 | U11: =IFERROR(IF(T11="",0,T11*N11/100),0) -> 0
B12: A1.1.3.2 | C12: Séance échange acteurs offre - Renforcement outils | D12: Output 1.1 | E12: BOUKARI AROUNA Rafiou | F12: BA KOTO Bona Sinani Rebecca | G12: 2 | H12: 46193 | I12: 46218 | L12: Suivi accompagnement | M12: =IF(OR(H12="",I12=""),0,IF(TODAY()<H12,0,IF(TODAY()>=I12,100,(TODAY()-H12)/(I12-H12)*100))) -> 0 | N12: 0 | O12: 198000 | Q12: =IF(B12="","",IF(K12<>"",IF(K12<=I12,"Terminé à temps","Terminé hors délai"),IF(N12=0,IF(TODAY()<H12,"En attente",IF(TODAY()>I12+30,"Critique","En retard")),IF(N12>=M12,"À temps",IF(N12>=M12*0.8,"À surveiller",IF(N12>=M12*0.5,"En retard","Critique")))))) -> En attente | R12: =IFERROR(IF(Q12="Terminé à temps",100,IF(Q12="Terminé hors délai",75,IF(Q12="À temps",50,IF(Q12="À surveiller",40,IF(Q12="En retard",25,IF(Q12="Critique",10,IF(Q12="En attente",50,0))))))),0) -> 50 | S12: Ind 1.1.6 | T12: 15 | U12: =IFERROR(IF(T12="",0,T12*N12/100),0) -> 0
B13: A1.2.1 | C13: Réalisation monographie sommaire | D13: Output 1.1 | E13: BOUKARI AROUNA Rafiou | F13: Consultant externe | G13: 2 | H13: 46204 | I13: 46233 | L13: TDR / Collecte / Rédaction | M13: =IF(OR(H13="",I13=""),0,IF(TODAY()<H13,0,IF(TODAY()>=I13,100,(TODAY()-H13)/(I13-H13)*100))) -> 0 | N13: 0 | O13: 435000 | Q13: =IF(B13="","",IF(K13<>"",IF(K13<=I13,"Terminé à temps","Terminé hors délai"),IF(N13=0,IF(TODAY()<H13,"En attente",IF(TODAY()>I13+30,"Critique","En retard")),IF(N13>=M13,"À temps",IF(N13>=M13*0.8,"À surveiller",IF(N13>=M13*0.5,"En retard","Critique")))))) -> En attente | R13: =IFERROR(IF(Q13="Terminé à temps",100,IF(Q13="Terminé hors délai",75,IF(Q13="À temps",50,IF(Q13="À surveiller",40,IF(Q13="En retard",25,IF(Q13="Critique",10,IF(Q13="En attente",50,0))))))),0) -> 50 | S13: Ind 1.1.3 | U13: =IFERROR(IF(T13="",0,T13*N13/100),0) -> 0
B14: A1.2.2.1 | C14: Auto-évaluation prestataires (acteurs offre) | D14: Output 1.1 | E14: BOUKARI AROUNA Rafiou | F14: BA KOTO Bona Sinani Rebecca | G14: 2 | H14: 46235 | I14: 46265 | L14: TDR / Atelier / Rapport | M14: =IF(OR(H14="",I14=""),0,IF(TODAY()<H14,0,IF(TODAY()>=I14,100,(TODAY()-H14)/(I14-H14)*100))) -> 0 | N14: 0 | O14: 424500 | Q14: =IF(B14="","",IF(K14<>"",IF(K14<=I14,"Terminé à temps","Terminé hors délai"),IF(N14=0,IF(TODAY()<H14,"En attente",IF(TODAY()>I14+30,"Critique","En retard")),IF(N14>=M14,"À temps",IF(N14>=M14*0.8,"À surveiller",IF(N14>=M14*0.5,"En retard","Critique")))))) -> En attente | R14: =IFERROR(IF(Q14="Terminé à temps",100,IF(Q14="Terminé hors délai",75,IF(Q14="À temps",50,IF(Q14="À surveiller",40,IF(Q14="En retard",25,IF(Q14="Critique",10,IF(Q14="En attente",50,0))))))),0) -> 50 | S14: Ind 1.1.3 | U14: =IFERROR(IF(T14="",0,T14*N14/100),0) -> 0
B15: A1.2.2.2 | C15: Évaluation qualité service par citoyens usagers (enquête satisfaction) | D15: Output 1.1 | E15: BOUKARI AROUNA Rafiou | F15: BA KOTO Bona Sinani Rebecca | G15: 3 | H15: 46266 | I15: 46295 | L15: TDR / Enquête / Rapport | M15: =IF(OR(H15="",I15=""),0,IF(TODAY()<H15,0,IF(TODAY()>=I15,100,(TODAY()-H15)/(I15-H15)*100))) -> 0 | N15: 0 | O15: 654000 | Q15: =IF(B15="","",IF(K15<>"",IF(K15<=I15,"Terminé à temps","Terminé hors délai"),IF(N15=0,IF(TODAY()<H15,"En attente",IF(TODAY()>I15+30,"Critique","En retard")),IF(N15>=M15,"À temps",IF(N15>=M15*0.8,"À surveiller",IF(N15>=M15*0.5,"En retard","Critique")))))) -> En attente | R15: =IFERROR(IF(Q15="Terminé à temps",100,IF(Q15="Terminé hors délai",75,IF(Q15="À temps",50,IF(Q15="À surveiller",40,IF(Q15="En retard",25,IF(Q15="Critique",10,IF(Q15="En attente",50,0))))))),0) -> 50 | S15: Ind 0.2 | T15: 1 | U15: =IFERROR(IF(T15="",0,T15*N15/100),0) -> 0
B16: A1.2.2.3 | C16: Séance face-à-face offre/demande - Forum dialogue | D16: Output 1.1 | E16: BOUKARI AROUNA Rafiou | F16: BA KOTO Bona Sinani Rebecca | G16: 3 | H16: 46296 | I16: 46325 | L16: TDR / Forum / PV | M16: =IF(OR(H16="",I16=""),0,IF(TODAY()<H16,0,IF(TODAY()>=I16,100,(TODAY()-H16)/(I16-H16)*100))) -> 0 | N16: 0 | O16: 572500 | Q16: =IF(B16="","",IF(K16<>"",IF(K16<=I16,"Terminé à temps","Terminé hors délai"),IF(N16=0,IF(TODAY()<H16,"En attente",IF(TODAY()>I16+30,"Critique","En retard")),IF(N16>=M16,"À temps",IF(N16>=M16*0.8,"À surveiller",IF(N16>=M16*0.5,"En retard","Critique")))))) -> En attente | R16: =IFERROR(IF(Q16="Terminé à temps",100,IF(Q16="Terminé hors délai",75,IF(Q16="À temps",50,IF(Q16="À surveiller",40,IF(Q16="En retard",25,IF(Q16="Critique",10,IF(Q16="En attente",50,0))))))),0) -> 50 | S16: Ind 1.3.1 | T16: 1 | U16: =IFERROR(IF(T16="",0,T16*N16/100),0) -> 0
B17: A1.2.E.1 | C17: Formation 75 élèves clubs scolaires (60% filles) | D17: Output 1.2 | E17: BA KOTO Bona Sinani Rebecca | F17: AMADOU Nafissatou | G17: 3 | H17: 46143 | I17: 46234 | L17: Liste nominative / Module | M17: =IF(OR(H17="",I17=""),0,IF(TODAY()<H17,0,IF(TODAY()>=I17,100,(TODAY()-H17)/(I17-H17)*100))) -> 26.373626 | N17: 0 | O17: 0 | Q17: =IF(B17="","",IF(K17<>"",IF(K17<=I17,"Terminé à temps","Terminé hors délai"),IF(N17=0,IF(TODAY()<H17,"En attente",IF(TODAY()>I17+30,"Critique","En retard")),IF(N17>=M17,"À temps",IF(N17>=M17*0.8,"À surveiller",IF(N17>=M17*0.5,"En retard","Critique")))))) -> En retard | R17: =IFERROR(IF(Q17="Terminé à temps",100,IF(Q17="Terminé hors délai",75,IF(Q17="À temps",50,IF(Q17="À surveiller",40,IF(Q17="En retard",25,IF(Q17="Critique",10,IF(Q17="En attente",50,0))))))),0) -> 25 | S17: Ind 1.2.1 | T17: 75 | U17: =IFERROR(IF(T17="",0,T17*N17/100),0) -> 0
B18: A1.2.E.2 | C18: Mise en œuvre plans animation clubs (5 clubs) | D18: Output 1.2 | E18: BA KOTO Bona Sinani Rebecca | F18: AMADOU Nafissatou | G18: 3 | H18: 46235 | I18: 46538 | L18: Plans animation / Suivi | M18: =IF(OR(H18="",I18=""),0,IF(TODAY()<H18,0,IF(TODAY()>=I18,100,(TODAY()-H18)/(I18-H18)*100))) -> 0 | N18: 0 | O18: 0 | Q18: =IF(B18="","",IF(K18<>"",IF(K18<=I18,"Terminé à temps","Terminé hors délai"),IF(N18=0,IF(TODAY()<H18,"En attente",IF(TODAY()>I18+30,"Critique","En retard")),IF(N18>=M18,"À temps",IF(N18>=M18*0.8,"À surveiller",IF(N18>=M18*0.5,"En retard","Critique")))))) -> En attente | R18: =IFERROR(IF(Q18="Terminé à temps",100,IF(Q18="Terminé hors délai",75,IF(Q18="À temps",50,IF(Q18="À surveiller",40,IF(Q18="En retard",25,IF(Q18="Critique",10,IF(Q18="En attente",50,0))))))),0) -> 50 | S18: Ind 1.2.2 | T18: 5 | U18: =IFERROR(IF(T18="",0,T18*N18/100),0) -> 0
B19: A1.3.1.1 | C19: Mise en œuvre 5 plans d'action communautaires (séances concertation) | D19: Output 1.3 | E19: BOUKARI AROUNA Rafiou | F19: BA KOTO Bona Sinani Rebecca, APE/AME | G19: 3 | H19: 46327 | I19: 46477 | L19: Plans validés / Suivi | M19: =IF(OR(H19="",I19=""),0,IF(TODAY()<H19,0,IF(TODAY()>=I19,100,(TODAY()-H19)/(I19-H19)*100))) -> 0 | N19: 0 | O19: 4500000 | Q19: =IF(B19="","",IF(K19<>"",IF(K19<=I19,"Terminé à temps","Terminé hors délai"),IF(N19=0,IF(TODAY()<H19,"En attente",IF(TODAY()>I19+30,"Critique","En retard")),IF(N19>=M19,"À temps",IF(N19>=M19*0.8,"À surveiller",IF(N19>=M19*0.5,"En retard","Critique")))))) -> En attente | R19: =IFERROR(IF(Q19="Terminé à temps",100,IF(Q19="Terminé hors délai",75,IF(Q19="À temps",50,IF(Q19="À surveiller",40,IF(Q19="En retard",25,IF(Q19="Critique",10,IF(Q19="En attente",50,0))))))),0) -> 50 | S19: Ind 1.3.2 | T19: 6 | U19: =IFERROR(IF(T19="",0,T19*N19/100),0) -> 0
B20: A1.3.1.2 | C20: Intégration recommandations dans plans communaux | D20: Output 1.3 | E20: KASSIMOU Mountarou | F20: BOUKARI AROUNA Rafiou | G20: 3 | H20: 46419 | I20: 46507 | L20: Plans communaux validés | M20: =IF(OR(H20="",I20=""),0,IF(TODAY()<H20,0,IF(TODAY()>=I20,100,(TODAY()-H20)/(I20-H20)*100))) -> 0 | N20: 0 | O20: 598133 | Q20: =IF(B20="","",IF(K20<>"",IF(K20<=I20,"Terminé à temps","Terminé hors délai"),IF(N20=0,IF(TODAY()<H20,"En attente",IF(TODAY()>I20+30,"Critique","En retard")),IF(N20>=M20,"À temps",IF(N20>=M20*0.8,"À surveiller",IF(N20>=M20*0.5,"En retard","Critique")))))) -> En attente | R20: =IFERROR(IF(Q20="Terminé à temps",100,IF(Q20="Terminé hors délai",75,IF(Q20="À temps",50,IF(Q20="À surveiller",40,IF(Q20="En retard",25,IF(Q20="Critique",10,IF(Q20="En attente",50,0))))))),0) -> 50 | S20: Ind 1.3.3 | T20: 3 | U20: =IFERROR(IF(T20="",0,T20*N20/100),0) -> 0
B21: A0.IMP | C21: Suivi annuel du taux d'abandon scolaire des filles | D21: Transverse | E21: BOUKARI AROUNA Rafiou | F21: CS/DDEMP | G21: 3 | H21: 46113 | I21: 46538 | L21: Données DDEMP | M21: =IF(OR(H21="",I21=""),0,IF(TODAY()<H21,0,IF(TODAY()>=I21,100,(TODAY()-H21)/(I21-H21)*100))) -> 12.705882 | N21: 0 | O21: 0 | Q21: =IF(B21="","",IF(K21<>"",IF(K21<=I21,"Terminé à temps","Terminé hors délai"),IF(N21=0,IF(TODAY()<H21,"En attente",IF(TODAY()>I21+30,"Critique","En retard")),IF(N21>=M21,"À temps",IF(N21>=M21*0.8,"À surveiller",IF(N21>=M21*0.5,"En retard","Critique")))))) -> En retard | R21: =IFERROR(IF(Q21="Terminé à temps",100,IF(Q21="Terminé hors délai",75,IF(Q21="À temps",50,IF(Q21="À surveiller",40,IF(Q21="En retard",25,IF(Q21="Critique",10,IF(Q21="En attente",50,0))))))),0) -> 25 | S21: Ind 0.1 | T21: 1 | U21: =IFERROR(IF(T21="",0,T21*N21/100),0) -> 0
B22: A0.2 | C22: Capitalisation et communication via radios locales | D22: Transverse | E22: BA KOTO Bona Sinani Rebecca | F22: Équipe + consultant | G22: 2 | H22: 46113 | I22: 46538 | L22: Bulletins / Émissions / Posts | M22: =IF(OR(H22="",I22=""),0,IF(TODAY()<H22,0,IF(TODAY()>=I22,100,(TODAY()-H22)/(I22-H22)*100))) -> 12.705882 | N22: 0 | O22: 1500000 | Q22: =IF(B22="","",IF(K22<>"",IF(K22<=I22,"Terminé à temps","Terminé hors délai"),IF(N22=0,IF(TODAY()<H22,"En attente",IF(TODAY()>I22+30,"Critique","En retard")),IF(N22>=M22,"À temps",IF(N22>=M22*0.8,"À surveiller",IF(N22>=M22*0.5,"En retard","Critique")))))) -> En retard | R22: =IFERROR(IF(Q22="Terminé à temps",100,IF(Q22="Terminé hors délai",75,IF(Q22="À temps",50,IF(Q22="À surveiller",40,IF(Q22="En retard",25,IF(Q22="Critique",10,IF(Q22="En attente",50,0))))))),0) -> 25 | U22: =IFERROR(IF(T22="",0,T22*N22/100),0) -> 0
B23: A0.3 | C23: 4 sessions du Comité de Pilotage (CoPil) | D23: Transverse | E23: KASSIMOU Mountarou | F23: Membres CoPil | G23: 2 | H23: 46113 | I23: 46538 | L23: 4 PV de CoPil | M23: =IF(OR(H23="",I23=""),0,IF(TODAY()<H23,0,IF(TODAY()>=I23,100,(TODAY()-H23)/(I23-H23)*100))) -> 12.705882 | N23: 0 | O23: 550000 | Q23: =IF(B23="","",IF(K23<>"",IF(K23<=I23,"Terminé à temps","Terminé hors délai"),IF(N23=0,IF(TODAY()<H23,"En attente",IF(TODAY()>I23+30,"Critique","En retard")),IF(N23>=M23,"À temps",IF(N23>=M23*0.8,"À surveiller",IF(N23>=M23*0.5,"En retard","Critique")))))) -> En retard | R23: =IFERROR(IF(Q23="Terminé à temps",100,IF(Q23="Terminé hors délai",75,IF(Q23="À temps",50,IF(Q23="À surveiller",40,IF(Q23="En retard",25,IF(Q23="Critique",10,IF(Q23="En attente",50,0))))))),0) -> 25 | U23: =IFERROR(IF(T23="",0,T23*N23/100),0) -> 0
B24: A0.4 | C24: Participation aux activités GFA | D24: Transverse | E24: BOUKARI AROUNA Rafiou | F24: Équipe | G24: 1 | H24: 46082 | I24: 46538 | L24: Liste participations | M24: =IF(OR(H24="",I24=""),0,IF(TODAY()<H24,0,IF(TODAY()>=I24,100,(TODAY()-H24)/(I24-H24)*100))) -> 18.640351 | N24: 0 | O24: 1000000 | Q24: =IF(B24="","",IF(K24<>"",IF(K24<=I24,"Terminé à temps","Terminé hors délai"),IF(N24=0,IF(TODAY()<H24,"En attente",IF(TODAY()>I24+30,"Critique","En retard")),IF(N24>=M24,"À temps",IF(N24>=M24*0.8,"À surveiller",IF(N24>=M24*0.5,"En retard","Critique")))))) -> En retard | R24: =IFERROR(IF(Q24="Terminé à temps",100,IF(Q24="Terminé hors délai",75,IF(Q24="À temps",50,IF(Q24="À surveiller",40,IF(Q24="En retard",25,IF(Q24="Critique",10,IF(Q24="En attente",50,0))))))),0) -> 25 | U24: =IFERROR(IF(T24="",0,T24*N24/100),0) -> 0
B25: A0.5 | C25: Atelier d'évaluation finale | D25: Transverse | E25: BOUKARI AROUNA Rafiou | F25: BA KOTO Bona Sinani Rebecca, ASSOUMA Nadjibatou | G25: 3 | H25: 46508 | I25: 46538 | L25: TDR / Atelier / Rapport final | M25: =IF(OR(H25="",I25=""),0,IF(TODAY()<H25,0,IF(TODAY()>=I25,100,(TODAY()-H25)/(I25-H25)*100))) -> 0 | N25: 0 | O25: 525000 | Q25: =IF(B25="","",IF(K25<>"",IF(K25<=I25,"Terminé à temps","Terminé hors délai"),IF(N25=0,IF(TODAY()<H25,"En attente",IF(TODAY()>I25+30,"Critique","En retard")),IF(N25>=M25,"À temps",IF(N25>=M25*0.8,"À surveiller",IF(N25>=M25*0.5,"En retard","Critique")))))) -> En attente | R25: =IFERROR(IF(Q25="Terminé à temps",100,IF(Q25="Terminé hors délai",75,IF(Q25="À temps",50,IF(Q25="À surveiller",40,IF(Q25="En retard",25,IF(Q25="Critique",10,IF(Q25="En attente",50,0))))))),0) -> 50 | U25: =IFERROR(IF(T25="",0,T25*N25/100),0) -> 0
B26: TOTAL | O26: =SUM(O6:O25) -> 12732633 | P26: =SUM(P6:P25) -> 0
M27: =IF(OR(B27="",H27="",I27=""),0,IF(TODAY()<H27,0,IF(TODAY()>=I27,100,(TODAY()-H27)/(I27-H27)*100))) -> 0 | N27: 0 | Q27: =IF(B27="","",IF(K27<>"",IF(K27<=I27,"Terminé à temps","Terminé hors délai"),IF(N27=0,IF(TODAY()<H27,"En attente",IF(TODAY()>I27+30,"Critique","En retard")),IF(N27>=M27,"À temps",IF(N27>=M27*0.8,"À surveiller",IF(N27>=M27*0.5,"En retard","Critique")))))) | R27: =IFERROR(IF(Q27="Terminé à temps",100,IF(Q27="Terminé hors délai",75,IF(Q27="À temps",50,IF(Q27="À surveiller",40,IF(Q27="En retard",25,IF(Q27="Critique",10,IF(Q27="En attente",50,0))))))),0) -> 0 | U27: =IFERROR(IF(T27="",0,T27*N27/100),0) -> 0
M28: =IF(OR(B28="",H28="",I28=""),0,IF(TODAY()<H28,0,IF(TODAY()>=I28,100,(TODAY()-H28)/(I28-H28)*100))) -> 0 | N28: 0 | Q28: =IF(B28="","",IF(K28<>"",IF(K28<=I28,"Terminé à temps","Terminé hors délai"),IF(N28=0,IF(TODAY()<H28,"En attente",IF(TODAY()>I28+30,"Critique","En retard")),IF(N28>=M28,"À temps",IF(N28>=M28*0.8,"À surveiller",IF(N28>=M28*0.5,"En retard","Critique")))))) | R28: =IFERROR(IF(Q28="Terminé à temps",100,IF(Q28="Terminé hors délai",75,IF(Q28="À temps",50,IF(Q28="À surveiller",40,IF(Q28="En retard",25,IF(Q28="Critique",10,IF(Q28="En attente",50,0))))))),0) -> 0 | U28: =IFERROR(IF(T28="",0,T28*N28/100),0) -> 0
M29: =IF(OR(B29="",H29="",I29=""),0,IF(TODAY()<H29,0,IF(TODAY()>=I29,100,(TODAY()-H29)/(I29-H29)*100))) -> 0 | N29: 0 | Q29: =IF(B29="","",IF(K29<>"",IF(K29<=I29,"Terminé à temps","Terminé hors délai"),IF(N29=0,IF(TODAY()<H29,"En attente",IF(TODAY()>I29+30,"Critique","En retard")),IF(N29>=M29,"À temps",IF(N29>=M29*0.8,"À surveiller",IF(N29>=M29*0.5,"En retard","Critique")))))) | R29: =IFERROR(IF(Q29="Terminé à temps",100,IF(Q29="Terminé hors délai",75,IF(Q29="À temps",50,IF(Q29="À surveiller",40,IF(Q29="En retard",25,IF(Q29="Critique",10,IF(Q29="En attente",50,0))))))),0) -> 0 | U29: =IFERROR(IF(T29="",0,T29*N29/100),0) -> 0
M30: =IF(OR(B30="",H30="",I30=""),0,IF(TODAY()<H30,0,IF(TODAY()>=I30,100,(TODAY()-H30)/(I30-H30)*100))) -> 0 | N30: 0 | Q30: =IF(B30="","",IF(K30<>"",IF(K30<=I30,"Terminé à temps","Terminé hors délai"),IF(N30=0,IF(TODAY()<H30,"En attente",IF(TODAY()>I30+30,"Critique","En retard")),IF(N30>=M30,"À temps",IF(N30>=M30*0.8,"À surveiller",IF(N30>=M30*0.5,"En retard","Critique")))))) | R30: =IFERROR(IF(Q30="Terminé à temps",100,IF(Q30="Terminé hors délai",75,IF(Q30="À temps",50,IF(Q30="À surveiller",40,IF(Q30="En retard",25,IF(Q30="Critique",10,IF(Q30="En attente",50,0))))))),0) -> 0 | U30: =IFERROR(IF(T30="",0,T30*N30/100),0) -> 0
M31: =IF(OR(B31="",H31="",I31=""),0,IF(TODAY()<H31,0,IF(TODAY()>=I31,100,(TODAY()-H31)/(I31-H31)*100))) -> 0 | N31: 0 | Q31: =IF(B31="","",IF(K31<>"",IF(K31<=I31,"Terminé à temps","Terminé hors délai"),IF(N31=0,IF(TODAY()<H31,"En attente",IF(TODAY()>I31+30,"Critique","En retard")),IF(N31>=M31,"À temps",IF(N31>=M31*0.8,"À surveiller",IF(N31>=M31*0.5,"En retard","Critique")))))) | R31: =IFERROR(IF(Q31="Terminé à temps",100,IF(Q31="Terminé hors délai",75,IF(Q31="À temps",50,IF(Q31="À surveiller",40,IF(Q31="En retard",25,IF(Q31="Critique",10,IF(Q31="En attente",50,0))))))),0) -> 0 | U31: =IFERROR(IF(T31="",0,T31*N31/100),0) -> 0
M32: =IF(OR(B32="",H32="",I32=""),0,IF(TODAY()<H32,0,IF(TODAY()>=I32,100,(TODAY()-H32)/(I32-H32)*100))) -> 0 | N32: 0 | Q32: =IF(B32="","",IF(K32<>"",IF(K32<=I32,"Terminé à temps","Terminé hors délai"),IF(N32=0,IF(TODAY()<H32,"En attente",IF(TODAY()>I32+30,"Critique","En retard")),IF(N32>=M32,"À temps",IF(N32>=M32*0.8,"À surveiller",IF(N32>=M32*0.5,"En retard","Critique")))))) | R32: =IFERROR(IF(Q32="Terminé à temps",100,IF(Q32="Terminé hors délai",75,IF(Q32="À temps",50,IF(Q32="À surveiller",40,IF(Q32="En retard",25,IF(Q32="Critique",10,IF(Q32="En attente",50,0))))))),0) -> 0 | U32: =IFERROR(IF(T32="",0,T32*N32/100),0) -> 0
M33: =IF(OR(B33="",H33="",I33=""),0,IF(TODAY()<H33,0,IF(TODAY()>=I33,100,(TODAY()-H33)/(I33-H33)*100))) -> 0 | N33: 0 | Q33: =IF(B33="","",IF(K33<>"",IF(K33<=I33,"Terminé à temps","Terminé hors délai"),IF(N33=0,IF(TODAY()<H33,"En attente",IF(TODAY()>I33+30,"Critique","En retard")),IF(N33>=M33,"À temps",IF(N33>=M33*0.8,"À surveiller",IF(N33>=M33*0.5,"En retard","Critique")))))) | R33: =IFERROR(IF(Q33="Terminé à temps",100,IF(Q33="Terminé hors délai",75,IF(Q33="À temps",50,IF(Q33="À surveiller",40,IF(Q33="En retard",25,IF(Q33="Critique",10,IF(Q33="En attente",50,0))))))),0) -> 0 | U33: =IFERROR(IF(T33="",0,T33*N33/100),0) -> 0
M34: =IF(OR(B34="",H34="",I34=""),0,IF(TODAY()<H34,0,IF(TODAY()>=I34,100,(TODAY()-H34)/(I34-H34)*100))) -> 0 | N34: 0 | Q34: =IF(B34="","",IF(K34<>"",IF(K34<=I34,"Terminé à temps","Terminé hors délai"),IF(N34=0,IF(TODAY()<H34,"En attente",IF(TODAY()>I34+30,"Critique","En retard")),IF(N34>=M34,"À temps",IF(N34>=M34*0.8,"À surveiller",IF(N34>=M34*0.5,"En retard","Critique")))))) | R34: =IFERROR(IF(Q34="Terminé à temps",100,IF(Q34="Terminé hors délai",75,IF(Q34="À temps",50,IF(Q34="À surveiller",40,IF(Q34="En retard",25,IF(Q34="Critique",10,IF(Q34="En attente",50,0))))))),0) -> 0 | U34: =IFERROR(IF(T34="",0,T34*N34/100),0) -> 0
M35: =IF(OR(B35="",H35="",I35=""),0,IF(TODAY()<H35,0,IF(TODAY()>=I35,100,(TODAY()-H35)/(I35-H35)*100))) -> 0 | N35: 0 | Q35: =IF(B35="","",IF(K35<>"",IF(K35<=I35,"Terminé à temps","Terminé hors délai"),IF(N35=0,IF(TODAY()<H35,"En attente",IF(TODAY()>I35+30,"Critique","En retard")),IF(N35>=M35,"À temps",IF(N35>=M35*0.8,"À surveiller",IF(N35>=M35*0.5,"En retard","Critique")))))) | R35: =IFERROR(IF(Q35="Terminé à temps",100,IF(Q35="Terminé hors délai",75,IF(Q35="À temps",50,IF(Q35="À surveiller",40,IF(Q35="En retard",25,IF(Q35="Critique",10,IF(Q35="En attente",50,0))))))),0) -> 0 | U35: =IFERROR(IF(T35="",0,T35*N35/100),0) -> 0
M36: =IF(OR(B36="",H36="",I36=""),0,IF(TODAY()<H36,0,IF(TODAY()>=I36,100,(TODAY()-H36)/(I36-H36)*100))) -> 0 | N36: 0 | Q36: =IF(B36="","",IF(K36<>"",IF(K36<=I36,"Terminé à temps","Terminé hors délai"),IF(N36=0,IF(TODAY()<H36,"En attente",IF(TODAY()>I36+30,"Critique","En retard")),IF(N36>=M36,"À temps",IF(N36>=M36*0.8,"À surveiller",IF(N36>=M36*0.5,"En retard","Critique")))))) | R36: =IFERROR(IF(Q36="Terminé à temps",100,IF(Q36="Terminé hors délai",75,IF(Q36="À temps",50,IF(Q36="À surveiller",40,IF(Q36="En retard",25,IF(Q36="Critique",10,IF(Q36="En attente",50,0))))))),0) -> 0 | U36: =IFERROR(IF(T36="",0,T36*N36/100),0) -> 0
M37: =IF(OR(B37="",H37="",I37=""),0,IF(TODAY()<H37,0,IF(TODAY()>=I37,100,(TODAY()-H37)/(I37-H37)*100))) -> 0 | N37: 0 | Q37: =IF(B37="","",IF(K37<>"",IF(K37<=I37,"Terminé à temps","Terminé hors délai"),IF(N37=0,IF(TODAY()<H37,"En attente",IF(TODAY()>I37+30,"Critique","En retard")),IF(N37>=M37,"À temps",IF(N37>=M37*0.8,"À surveiller",IF(N37>=M37*0.5,"En retard","Critique")))))) | R37: =IFERROR(IF(Q37="Terminé à temps",100,IF(Q37="Terminé hors délai",75,IF(Q37="À temps",50,IF(Q37="À surveiller",40,IF(Q37="En retard",25,IF(Q37="Critique",10,IF(Q37="En attente",50,0))))))),0) -> 0 | U37: =IFERROR(IF(T37="",0,T37*N37/100),0) -> 0
M38: =IF(OR(B38="",H38="",I38=""),0,IF(TODAY()<H38,0,IF(TODAY()>=I38,100,(TODAY()-H38)/(I38-H38)*100))) -> 0 | N38: 0 | Q38: =IF(B38="","",IF(K38<>"",IF(K38<=I38,"Terminé à temps","Terminé hors délai"),IF(N38=0,IF(TODAY()<H38,"En attente",IF(TODAY()>I38+30,"Critique","En retard")),IF(N38>=M38,"À temps",IF(N38>=M38*0.8,"À surveiller",IF(N38>=M38*0.5,"En retard","Critique")))))) | R38: =IFERROR(IF(Q38="Terminé à temps",100,IF(Q38="Terminé hors délai",75,IF(Q38="À temps",50,IF(Q38="À surveiller",40,IF(Q38="En retard",25,IF(Q38="Critique",10,IF(Q38="En attente",50,0))))))),0) -> 0 | U38: =IFERROR(IF(T38="",0,T38*N38/100),0) -> 0
... M200: =IF(OR(B200="",H200="",I200=""),0,IF(TODAY()<H200,0,IF(TODAY()>=I200,100,(TODAY()-H200)/(I200-H200)*100))) -> 0 | N200: 0 | Q200: =IF(B200="","",IF(K200<>"",IF(K200<=I200,"Terminé à temps","Terminé hors délai"),IF(N200=0,IF(TODAY()<H200,"En attente",IF(TODAY()>I200+30,"Critique","En retard")),IF(N200>=M200,"À temps",IF(N200>=M200*0.8,"À surveiller",IF(N200>=M200*0.5,"En retard","Critique")))))) | R200: =IFERROR(IF(Q200="Terminé à temps",100,IF(Q200="Terminé hors délai",75,IF(Q200="À temps",50,IF(Q200="À surveiller",40,IF(Q200="En retard",25,IF(Q200="Critique",10,IF(Q200="En attente",50,0))))))),0) -> 0 | U200: =IFERROR(IF(T200="",0,T200*N200/100),0) -> 0

Sheet 6. Indicateurs EQUIFILLES
B2: TABLEAU DE BORD DES INDICATEURS — EQUIFILLES (lecture seule)
B3: ⚠ Cet onglet est en lecture seule. Les indicateurs sont alimentés AUTOMATIQUEMENT par le Gantt (onglet 5) et l'outil de Collecte (onglet 7). Pour modifier les valeurs, agissez sur les Gantt ou la Collecte.
B5: Code | C5: Indicateur | D5: Niveau | E5: Cible | F5: Baseline | G5: Valeur Gantt | H5: Valeur Collecte | I5: Valeur cumulée | J5: % atteinte | K5: Statut | L5: Source données
B6: Ind 0.1 | C6: Taux d'abandon scolaire des filles réduit | D6: Impact | E6: 30 | F6: 0 | G6: =IFERROR(SUMIF('5. Gantt EQUIFILLES'!S6:S200,B6,'5. Gantt EQUIFILLES'!U6:U200),0) -> 0 | H6: =IFERROR(VLOOKUP(B6,'7. Collecte EQUIFILLES'!B:I,8,FALSE()),0) -> 0 | I6: =IF(H6>0,H6,G6) -> 0 | J6: =IFERROR(I6/E6,0) -> 0 | K6: =IF(J6>=1,"Atteint",IF(J6>=0.75,"En bonne voie",IF(J6>=0.5,"À surveiller",IF(J6>0,"En retard","Non démarré")))) -> Non démarré | L6: Enquête + DDEMP
B7: Ind 0.2 | C7: Niveau de satisfaction parents/élèves | D7: Impact | E7: 75 | F7: 0 | G7: =IFERROR(SUMIF('5. Gantt EQUIFILLES'!S6:S200,B7,'5. Gantt EQUIFILLES'!U6:U200),0) -> 0 | H7: =IFERROR(VLOOKUP(B7,'7. Collecte EQUIFILLES'!B:I,8,FALSE()),0) -> 0 | I7: =IF(H7>0,H7,G7) -> 0 | J7: =IFERROR(I7/E7,0) -> 0 | K7: =IF(J7>=1,"Atteint",IF(J7>=0.75,"En bonne voie",IF(J7>=0.5,"À surveiller",IF(J7>0,"En retard","Non démarré")))) -> Non démarré | L7: Enquête de satisfaction
B8: Ind 1.1.1 | C8: 30 APE/AME/CAPE et CGS formés | D8: Output 1.1 | E8: 30 | F8: 0 | G8: =IFERROR(SUMIF('5. Gantt EQUIFILLES'!S6:S200,B8,'5. Gantt EQUIFILLES'!U6:U200),0) -> 0 | H8: =IFERROR(VLOOKUP(B8,'7. Collecte EQUIFILLES'!B:I,8,FALSE()),0) -> 0 | I8: =IF(H8>0,H8,G8) -> 0 | J8: =IFERROR(I8/E8,0) -> 0 | K8: =IF(J8>=1,"Atteint",IF(J8>=0.75,"En bonne voie",IF(J8>=0.5,"À surveiller",IF(J8>0,"En retard","Non démarré")))) -> Non démarré | L8: Activités A1.1.2.1
B9: Ind 1.1.2 | C9: ≥ 80% APE/AME participent aux cycles | D9: Output 1.1 | E9: 80 | F9: 0 | G9: =IFERROR(SUMIF('5. Gantt EQUIFILLES'!S6:S200,B9,'5. Gantt EQUIFILLES'!U6:U200),0) -> 0 | H9: =IFERROR(VLOOKUP(B9,'7. Collecte EQUIFILLES'!B:I,8,FALSE()),0) -> 0 | I9: =IF(H9>0,H9,G9) -> 0 | J9: =IFERROR(I9/E9,0) -> 0 | K9: =IF(J9>=1,"Atteint",IF(J9>=0.75,"En bonne voie",IF(J9>=0.5,"À surveiller",IF(J9>0,"En retard","Non démarré")))) -> Non démarré | L9: Activités A1.1.2.3 + Collecte
B10: Ind 1.1.3 | C10: 01 rapport d'évaluation citoyenne validé | D10: Output 1.1 | E10: 1 | F10: 0 | G10: =IFERROR(SUMIF('5. Gantt EQUIFILLES'!S6:S200,B10,'5. Gantt EQUIFILLES'!U6:U200),0) -> 0 | H10: =IFERROR(VLOOKUP(B10,'7. Collecte EQUIFILLES'!B:I,8,FALSE()),0) -> 0 | I10: =IF(H10>0,H10,G10) -> 0 | J10: =IFERROR(I10/E10,0) -> 0 | K10: =IF(J10>=1,"Atteint",IF(J10>=0.75,"En bonne voie",IF(J10>=0.5,"À surveiller",IF(J10>0,"En retard","Non démarré")))) -> Non démarré | L10: Activités A1.1.1, A1.2.1, A1.2.2
B11: Ind 1.1.4 | C11: Acteurs offre formés aux outils de redevabilité | D11: Output 1.1 | E11: 15 | F11: 0 | G11: =IFERROR(SUMIF('5. Gantt EQUIFILLES'!S6:S200,B11,'5. Gantt EQUIFILLES'!U6:U200),0) -> 0 | H11: =IFERROR(VLOOKUP(B11,'7. Collecte EQUIFILLES'!B:I,8,FALSE()),0) -> 0 | I11: =IF(H11>0,H11,G11) -> 0 | J11: =IFERROR(I11/E11,0) -> 0 | K11: =IF(J11>=1,"Atteint",IF(J11>=0.75,"En bonne voie",IF(J11>=0.5,"À surveiller",IF(J11>0,"En retard","Non démarré")))) -> Non démarré | L11: Activité A1.1.3.1
B12: Ind 1.1.5 | C12: Proportion de femmes formées | D12: Output 1.1 | E12: 50 | F12: 0 | G12: =IFERROR(SUMIF('5. Gantt EQUIFILLES'!S6:S200,B12,'5. Gantt EQUIFILLES'!U6:U200),0) -> 0 | H12: =IFERROR(VLOOKUP(B12,'7. Collecte EQUIFILLES'!B:I,8,FALSE()),0) -> 0 | I12: =IF(H12>0,H12,G12) -> 0 | J12: =IFERROR(I12/E12,0) -> 0 | K12: =IF(J12>=1,"Atteint",IF(J12>=0.75,"En bonne voie",IF(J12>=0.5,"À surveiller",IF(J12>0,"En retard","Non démarré")))) -> Non démarré | L12: Activité A1.1.2.2 + Collecte
B13: Ind 1.1.6 | C13: Acteurs offre renforcés sur outils | D13: Output 1.1 | E13: 15 | F13: 0 | G13: =IFERROR(SUMIF('5. Gantt EQUIFILLES'!S6:S200,B13,'5. Gantt EQUIFILLES'!U6:U200),0) -> 0 | H13: =IFERROR(VLOOKUP(B13,'7. Collecte EQUIFILLES'!B:I,8,FALSE()),0) -> 0 | I13: =IF(H13>0,H13,G13) -> 0 | J13: =IFERROR(I13/E13,0) -> 0 | K13: =IF(J13>=1,"Atteint",IF(J13>=0.75,"En bonne voie",IF(J13>=0.5,"À surveiller",IF(J13>0,"En retard","Non démarré")))) -> Non démarré | L13: Activité A1.1.3.2
B14: Ind 1.2.1 | C14: 75 élèves formés (60% filles) | D14: Output 1.2 | E14: 75 | F14: 0 | G14: =IFERROR(SUMIF('5. Gantt EQUIFILLES'!S6:S200,B14,'5. Gantt EQUIFILLES'!U6:U200),0) -> 0 | H14: =IFERROR(VLOOKUP(B14,'7. Collecte EQUIFILLES'!B:I,8,FALSE()),0) -> 0 | I14: =IF(H14>0,H14,G14) -> 0 | J14: =IFERROR(I14/E14,0) -> 0 | K14: =IF(J14>=1,"Atteint",IF(J14>=0.75,"En bonne voie",IF(J14>=0.5,"À surveiller",IF(J14>0,"En retard","Non démarré")))) -> Non démarré | L14: Activité A1.2.E.1
B15: Ind 1.2.2 | C15: ≥ 70% des actions plans clubs réalisées | D15: Output 1.2 | E15: 70 | F15: 0 | G15: =IFERROR(SUMIF('5. Gantt EQUIFILLES'!S6:S200,B15,'5. Gantt EQUIFILLES'!U6:U200),0) -> 0 | H15: =IFERROR(VLOOKUP(B15,'7. Collecte EQUIFILLES'!B:I,8,FALSE()),0) -> 0 | I15: =IF(H15>0,H15,G15) -> 0 | J15: =IFERROR(I15/E15,0) -> 0 | K15: =IF(J15>=1,"Atteint",IF(J15>=0.75,"En bonne voie",IF(J15>=0.5,"À surveiller",IF(J15>0,"En retard","Non démarré")))) -> Non démarré | L15: Activité A1.2.E.2 + Collecte
B16: Ind 1.3.1 | C16: ≥ 75% participation parents aux forums | D16: Output 1.3 | E16: 75 | F16: 0 | G16: =IFERROR(SUMIF('5. Gantt EQUIFILLES'!S6:S200,B16,'5. Gantt EQUIFILLES'!U6:U200),0) -> 0 | H16: =IFERROR(VLOOKUP(B16,'7. Collecte EQUIFILLES'!B:I,8,FALSE()),0) -> 0 | I16: =IF(H16>0,H16,G16) -> 0 | J16: =IFERROR(I16/E16,0) -> 0 | K16: =IF(J16>=1,"Atteint",IF(J16>=0.75,"En bonne voie",IF(J16>=0.5,"À surveiller",IF(J16>0,"En retard","Non démarré")))) -> Non démarré | L16: Activité A1.2.2.3 + Collecte
B17: Ind 1.3.2 | C17: 6 séances de concertation | D17: Output 1.3 | E17: 6 | F17: 0 | G17: =IFERROR(SUMIF('5. Gantt EQUIFILLES'!S6:S200,B17,'5. Gantt EQUIFILLES'!U6:U200),0) -> 0 | H17: =IFERROR(VLOOKUP(B17,'7. Collecte EQUIFILLES'!B:I,8,FALSE()),0) -> 0 | I17: =IF(H17>0,H17,G17) -> 0 | J17: =IFERROR(I17/E17,0) -> 0 | K17: =IF(J17>=1,"Atteint",IF(J17>=0.75,"En bonne voie",IF(J17>=0.5,"À surveiller",IF(J17>0,"En retard","Non démarré")))) -> Non démarré | L17: Activité A1.3.1.1
B18: Ind 1.3.3 | C18: ≥ 3 recommandations intégrées dans plans | D18: Output 1.3 | E18: 3 | F18: 0 | G18: =IFERROR(SUMIF('5. Gantt EQUIFILLES'!S6:S200,B18,'5. Gantt EQUIFILLES'!U6:U200),0) -> 0 | H18: =IFERROR(VLOOKUP(B18,'7. Collecte EQUIFILLES'!B:I,8,FALSE()),0) -> 0 | I18: =IF(H18>0,H18,G18) -> 0 | J18: =IFERROR(I18/E18,0) -> 0 | K18: =IF(J18>=1,"Atteint",IF(J18>=0.75,"En bonne voie",IF(J18>=0.5,"À surveiller",IF(J18>0,"En retard","Non démarré")))) -> Non démarré | L18: Activité A1.3.1.2
B19: SYNTHÈSE GLOBALE DES INDICATEURS | J19: =AVERAGE(J6:J18) -> 0 | K19: =COUNTIF(K6:K18,"Atteint")&"/"&13 -> 0/13 | L19: ← Atteints / Total

Sheet 7. Collecte EQUIFILLES
B2: OUTIL DE COLLECTE — EQUIFILLES (alimenté par KoboCollect)
B3: Les valeurs sont calculées AUTOMATIQUEMENT à partir de l'onglet "K1. Données Kobo EQUIFILLES". Il suffit de coller les exports Kobo dans cet onglet — la Collecte et les Indicateurs se mettent à jour seuls.
B5: Code Ind | C5: Indicateur | D5: Formulaire Kobo | E5: Mode d'agrégation | F5: Périodicité | G5: Nb soumissions Kobo | H5: Valeur brute Kobo | I5: Valeur retenue | J5: Unité | K5: Date dernière collecte | L5: Saisie manuelle (option) | M5: Observations
B6: Ind 0.1 | C6: Taux d'abandon scolaire des filles | D6: F3-Données scolaires | E6: Moyenne | F6: Annuel | G6: =COUNTIF('K1. Données Kobo EQUIFILLES'!$C$13:$C$500,B6) -> 0 | H6: =IF(E6="Somme",SUMIF('K1. Données Kobo EQUIFILLES'!$C$13:$C$500,B6,'K1. Données Kobo EQUIFILLES'!$I$13:$I$500),IF(E6="Comptage",COUNTIF('K1. Données Kobo EQUIFILLES'!$C$13:$C$500,B6),IF(E6="Moyenne",IFERROR(AVERAGEIF('K1. Données Kobo EQUIFILLES'!$C$13:$C$500,B6,'K1. Données Kobo EQUIFILLES'!$I$13:$I$500),0),0))) -> 0 | I6: =IF(L6<>"",L6,H6) -> 0 | J6: % | K6: =IFERROR(maxifs('K1. Données Kobo EQUIFILLES'!$E$13:$E$500,'K1. Données Kobo EQUIFILLES'!$C$13:$C$500,B6),"")
B7: Ind 0.2 | C7: Satisfaction parents et élèves | D7: F2-Enquête satisfaction | E7: Moyenne | F7: Semestrielle | G7: =COUNTIF('K1. Données Kobo EQUIFILLES'!$C$13:$C$500,B7) -> 0 | H7: =IF(E7="Somme",SUMIF('K1. Données Kobo EQUIFILLES'!$C$13:$C$500,B7,'K1. Données Kobo EQUIFILLES'!$I$13:$I$500),IF(E7="Comptage",COUNTIF('K1. Données Kobo EQUIFILLES'!$C$13:$C$500,B7),IF(E7="Moyenne",IFERROR(AVERAGEIF('K1. Données Kobo EQUIFILLES'!$C$13:$C$500,B7,'K1. Données Kobo EQUIFILLES'!$I$13:$I$500),0),0))) -> 0 | I7: =IF(L7<>"",L7,H7) -> 0 | J7: % | K7: =IFERROR(maxifs('K1. Données Kobo EQUIFILLES'!$E$13:$E$500,'K1. Données Kobo EQUIFILLES'!$C$13:$C$500,B7),"")
B8: Ind 1.1.2 | C8: Participation APE/AME aux cycles | D8: F1-Liste présence | E8: Comptage | F8: Trimestrielle | G8: =COUNTIF('K1. Données Kobo EQUIFILLES'!$C$13:$C$500,B8) -> 0 | H8: =IF(E8="Somme",SUMIF('K1. Données Kobo EQUIFILLES'!$C$13:$C$500,B8,'K1. Données Kobo EQUIFILLES'!$I$13:$I$500),IF(E8="Comptage",COUNTIF('K1. Données Kobo EQUIFILLES'!$C$13:$C$500,B8),IF(E8="Moyenne",IFERROR(AVERAGEIF('K1. Données Kobo EQUIFILLES'!$C$13:$C$500,B8,'K1. Données Kobo EQUIFILLES'!$I$13:$I$500),0),0))) -> 0 | I8: =IF(L8<>"",L8,H8) -> 0 | J8: Nb | K8: =IFERROR(maxifs('K1. Données Kobo EQUIFILLES'!$E$13:$E$500,'K1. Données Kobo EQUIFILLES'!$C$13:$C$500,B8),"")
B9: Ind 1.1.5 | C9: Proportion de femmes formées | D9: F1-Liste présence | E9: Comptage | F9: Ponctuelle | G9: =COUNTIF('K1. Données Kobo EQUIFILLES'!$C$13:$C$500,B9) -> 0 | H9: =IF(E9="Somme",SUMIF('K1. Données Kobo EQUIFILLES'!$C$13:$C$500,B9,'K1. Données Kobo EQUIFILLES'!$I$13:$I$500),IF(E9="Comptage",COUNTIF('K1. Données Kobo EQUIFILLES'!$C$13:$C$500,B9),IF(E9="Moyenne",IFERROR(AVERAGEIF('K1. Données Kobo EQUIFILLES'!$C$13:$C$500,B9,'K1. Données Kobo EQUIFILLES'!$I$13:$I$500),0),0))) -> 0 | I9: =IF(L9<>"",L9,H9) -> 0 | J9: Nb | K9: =IFERROR(maxifs('K1. Données Kobo EQUIFILLES'!$E$13:$E$500,'K1. Données Kobo EQUIFILLES'!$C$13:$C$500,B9),"")
B10: Ind 1.2.2 | C10: % actions d'animation réalisées | D10: F4-Suivi clubs | E10: Moyenne | F10: Trimestrielle | G10: =COUNTIF('K1. Données Kobo EQUIFILLES'!$C$13:$C$500,B10) -> 0 | H10: =IF(E10="Somme",SUMIF('K1. Données Kobo EQUIFILLES'!$C$13:$C$500,B10,'K1. Données Kobo EQUIFILLES'!$I$13:$I$500),IF(E10="Comptage",COUNTIF('K1. Données Kobo EQUIFILLES'!$C$13:$C$500,B10),IF(E10="Moyenne",IFERROR(AVERAGEIF('K1. Données Kobo EQUIFILLES'!$C$13:$C$500,B10,'K1. Données Kobo EQUIFILLES'!$I$13:$I$500),0),0))) -> 0 | I10: =IF(L10<>"",L10,H10) -> 0 | J10: % | K10: =IFERROR(maxifs('K1. Données Kobo EQUIFILLES'!$E$13:$E$500,'K1. Données Kobo EQUIFILLES'!$C$13:$C$500,B10),"")
B11: Ind 1.3.1 | C11: Participation parents aux forums | D11: F1-Liste présence | E11: Comptage | F11: Ponctuelle | G11: =COUNTIF('K1. Données Kobo EQUIFILLES'!$C$13:$C$500,B11) -> 0 | H11: =IF(E11="Somme",SUMIF('K1. Données Kobo EQUIFILLES'!$C$13:$C$500,B11,'K1. Données Kobo EQUIFILLES'!$I$13:$I$500),IF(E11="Comptage",COUNTIF('K1. Données Kobo EQUIFILLES'!$C$13:$C$500,B11),IF(E11="Moyenne",IFERROR(AVERAGEIF('K1. Données Kobo EQUIFILLES'!$C$13:$C$500,B11,'K1. Données Kobo EQUIFILLES'!$I$13:$I$500),0),0))) -> 0 | I11: =IF(L11<>"",L11,H11) -> 0 | J11: Nb | K11: =IFERROR(maxifs('K1. Données Kobo EQUIFILLES'!$E$13:$E$500,'K1. Données Kobo EQUIFILLES'!$C$13:$C$500,B11),"")
B12: Ind 1.3.3 | C12: Recommandations intégrées dans plans | D12: F5-Suivi plans | E12: Comptage | F12: Annuelle | G12: =COUNTIF('K1. Données Kobo EQUIFILLES'!$C$13:$C$500,B12) -> 0 | H12: =IF(E12="Somme",SUMIF('K1. Données Kobo EQUIFILLES'!$C$13:$C$500,B12,'K1. Données Kobo EQUIFILLES'!$I$13:$I$500),IF(E12="Comptage",COUNTIF('K1. Données Kobo EQUIFILLES'!$C$13:$C$500,B12),IF(E12="Moyenne",IFERROR(AVERAGEIF('K1. Données Kobo EQUIFILLES'!$C$13:$C$500,B12,'K1. Données Kobo EQUIFILLES'!$I$13:$I$500),0),0))) -> 0 | I12: =IF(L12<>"",L12,H12) -> 0 | J12: Nb | K12: =IFERROR(maxifs('K1. Données Kobo EQUIFILLES'!$E$13:$E$500,'K1. Données Kobo EQUIFILLES'!$C$13:$C$500,B12),"")
G13: =IF(B13="","",COUNTIF('K1. Données Kobo EQUIFILLES'!$C$13:$C$500,B13)) | H13: =IF(B13="","",IF(E13="Somme",SUMIF('K1. Données Kobo EQUIFILLES'!$C$13:$C$500,B13,'K1. Données Kobo EQUIFILLES'!$I$13:$I$500),IF(E13="Comptage",COUNTIF('K1. Données Kobo EQUIFILLES'!$C$13:$C$500,B13),IF(E13="Moyenne",IFERROR(AVERAGEIF('K1. Données Kobo EQUIFILLES'!$C$13:$C$500,B13,'K1. Données Kobo EQUIFILLES'!$I$13:$I$500),0),0)))) | I13: =IF(B13="","",IF(L13<>"",L13,H13)) | K13: =IF(B13="","",IFERROR(maxifs('K1. Données Kobo EQUIFILLES'!$E$13:$E$500,'K1. Données Kobo EQUIFILLES'!$C$13:$C$500,B13),""))
G14: =IF(B14="","",COUNTIF('K1. Données Kobo EQUIFILLES'!$C$13:$C$500,B14)) | H14: =IF(B14="","",IF(E14="Somme",SUMIF('K1. Données Kobo EQUIFILLES'!$C$13:$C$500,B14,'K1. Données Kobo EQUIFILLES'!$I$13:$I$500),IF(E14="Comptage",COUNTIF('K1. Données Kobo EQUIFILLES'!$C$13:$C$500,B14),IF(E14="Moyenne",IFERROR(AVERAGEIF('K1. Données Kobo EQUIFILLES'!$C$13:$C$500,B14,'K1. Données Kobo EQUIFILLES'!$I$13:$I$500),0),0)))) | I14: =IF(B14="","",IF(L14<>"",L14,H14)) | K14: =IF(B14="","",IFERROR(maxifs('K1. Données Kobo EQUIFILLES'!$E$13:$E$500,'K1. Données Kobo EQUIFILLES'!$C$13:$C$500,B14),""))
G15: =IF(B15="","",COUNTIF('K1. Données Kobo EQUIFILLES'!$C$13:$C$500,B15)) | H15: =IF(B15="","",IF(E15="Somme",SUMIF('K1. Données Kobo EQUIFILLES'!$C$13:$C$500,B15,'K1. Données Kobo EQUIFILLES'!$I$13:$I$500),IF(E15="Comptage",COUNTIF('K1. Données Kobo EQUIFILLES'!$C$13:$C$500,B15),IF(E15="Moyenne",IFERROR(AVERAGEIF('K1. Données Kobo EQUIFILLES'!$C$13:$C$500,B15,'K1. Données Kobo EQUIFILLES'!$I$13:$I$500),0),0)))) | I15: =IF(B15="","",IF(L15<>"",L15,H15)) | K15: =IF(B15="","",IFERROR(maxifs('K1. Données Kobo EQUIFILLES'!$E$13:$E$500,'K1. Données Kobo EQUIFILLES'!$C$13:$C$500,B15),""))
G16: =IF(B16="","",COUNTIF('K1. Données Kobo EQUIFILLES'!$C$13:$C$500,B16)) | H16: =IF(B16="","",IF(E16="Somme",SUMIF('K1. Données Kobo EQUIFILLES'!$C$13:$C$500,B16,'K1. Données Kobo EQUIFILLES'!$I$13:$I$500),IF(E16="Comptage",COUNTIF('K1. Données Kobo EQUIFILLES'!$C$13:$C$500,B16),IF(E16="Moyenne",IFERROR(AVERAGEIF('K1. Données Kobo EQUIFILLES'!$C$13:$C$500,B16,'K1. Données Kobo EQUIFILLES'!$I$13:$I$500),0),0)))) | I16: =IF(B16="","",IF(L16<>"",L16,H16)) | K16: =IF(B16="","",IFERROR(maxifs('K1. Données Kobo EQUIFILLES'!$E$13:$E$500,'K1. Données Kobo EQUIFILLES'!$C$13:$C$500,B16),""))
G17: =IF(B17="","",COUNTIF('K1. Données Kobo EQUIFILLES'!$C$13:$C$500,B17)) | H17: =IF(B17="","",IF(E17="Somme",SUMIF('K1. Données Kobo EQUIFILLES'!$C$13:$C$500,B17,'K1. Données Kobo EQUIFILLES'!$I$13:$I$500),IF(E17="Comptage",COUNTIF('K1. Données Kobo EQUIFILLES'!$C$13:$C$500,B17),IF(E17="Moyenne",IFERROR(AVERAGEIF('K1. Données Kobo EQUIFILLES'!$C$13:$C$500,B17,'K1. Données Kobo EQUIFILLES'!$I$13:$I$500),0),0)))) | I17: =IF(B17="","",IF(L17<>"",L17,H17)) | K17: =IF(B17="","",IFERROR(maxifs('K1. Données Kobo EQUIFILLES'!$E$13:$E$500,'K1. Données Kobo EQUIFILLES'!$C$13:$C$500,B17),""))
G18: =IF(B18="","",COUNTIF('K1. Données Kobo EQUIFILLES'!$C$13:$C$500,B18)) | H18: =IF(B18="","",IF(E18="Somme",SUMIF('K1. Données Kobo EQUIFILLES'!$C$13:$C$500,B18,'K1. Données Kobo EQUIFILLES'!$I$13:$I$500),IF(E18="Comptage",COUNTIF('K1. Données Kobo EQUIFILLES'!$C$13:$C$500,B18),IF(E18="Moyenne",IFERROR(AVERAGEIF('K1. Données Kobo EQUIFILLES'!$C$13:$C$500,B18,'K1. Données Kobo EQUIFILLES'!$I$13:$I$500),0),0)))) | I18: =IF(B18="","",IF(L18<>"",L18,H18)) | K18: =IF(B18="","",IFERROR(maxifs('K1. Données Kobo EQUIFILLES'!$E$13:$E$500,'K1. Données Kobo EQUIFILLES'!$C$13:$C$500,B18),""))
G19: =IF(B19="","",COUNTIF('K1. Données Kobo EQUIFILLES'!$C$13:$C$500,B19)) | H19: =IF(B19="","",IF(E19="Somme",SUMIF('K1. Données Kobo EQUIFILLES'!$C$13:$C$500,B19,'K1. Données Kobo EQUIFILLES'!$I$13:$I$500),IF(E19="Comptage",COUNTIF('K1. Données Kobo EQUIFILLES'!$C$13:$C$500,B19),IF(E19="Moyenne",IFERROR(AVERAGEIF('K1. Données Kobo EQUIFILLES'!$C$13:$C$500,B19,'K1. Données Kobo EQUIFILLES'!$I$13:$I$500),0),0)))) | I19: =IF(B19="","",IF(L19<>"",L19,H19)) | K19: =IF(B19="","",IFERROR(maxifs('K1. Données Kobo EQUIFILLES'!$E$13:$E$500,'K1. Données Kobo EQUIFILLES'!$C$13:$C$500,B19),""))
G20: =IF(B20="","",COUNTIF('K1. Données Kobo EQUIFILLES'!$C$13:$C$500,B20)) | H20: =IF(B20="","",IF(E20="Somme",SUMIF('K1. Données Kobo EQUIFILLES'!$C$13:$C$500,B20,'K1. Données Kobo EQUIFILLES'!$I$13:$I$500),IF(E20="Comptage",COUNTIF('K1. Données Kobo EQUIFILLES'!$C$13:$C$500,B20),IF(E20="Moyenne",IFERROR(AVERAGEIF('K1. Données Kobo EQUIFILLES'!$C$13:$C$500,B20,'K1. Données Kobo EQUIFILLES'!$I$13:$I$500),0),0)))) | I20: =IF(B20="","",IF(L20<>"",L20,H20)) | K20: =IF(B20="","",IFERROR(maxifs('K1. Données Kobo EQUIFILLES'!$E$13:$E$500,'K1. Données Kobo EQUIFILLES'!$C$13:$C$500,B20),""))
G21: =IF(B21="","",COUNTIF('K1. Données Kobo EQUIFILLES'!$C$13:$C$500,B21)) | H21: =IF(B21="","",IF(E21="Somme",SUMIF('K1. Données Kobo EQUIFILLES'!$C$13:$C$500,B21,'K1. Données Kobo EQUIFILLES'!$I$13:$I$500),IF(E21="Comptage",COUNTIF('K1. Données Kobo EQUIFILLES'!$C$13:$C$500,B21),IF(E21="Moyenne",IFERROR(AVERAGEIF('K1. Données Kobo EQUIFILLES'!$C$13:$C$500,B21,'K1. Données Kobo EQUIFILLES'!$I$13:$I$500),0),0)))) | I21: =IF(B21="","",IF(L21<>"",L21,H21)) | K21: =IF(B21="","",IFERROR(maxifs('K1. Données Kobo EQUIFILLES'!$E$13:$E$500,'K1. Données Kobo EQUIFILLES'!$C$13:$C$500,B21),""))
G22: =IF(B22="","",COUNTIF('K1. Données Kobo EQUIFILLES'!$C$13:$C$500,B22)) | H22: =IF(B22="","",IF(E22="Somme",SUMIF('K1. Données Kobo EQUIFILLES'!$C$13:$C$500,B22,'K1. Données Kobo EQUIFILLES'!$I$13:$I$500),IF(E22="Comptage",COUNTIF('K1. Données Kobo EQUIFILLES'!$C$13:$C$500,B22),IF(E22="Moyenne",IFERROR(AVERAGEIF('K1. Données Kobo EQUIFILLES'!$C$13:$C$500,B22,'K1. Données Kobo EQUIFILLES'!$I$13:$I$500),0),0)))) | I22: =IF(B22="","",IF(L22<>"",L22,H22)) | K22: =IF(B22="","",IFERROR(maxifs('K1. Données Kobo EQUIFILLES'!$E$13:$E$500,'K1. Données Kobo EQUIFILLES'!$C$13:$C$500,B22),""))
